<?xml version="1.0"?><robot name="pepe">
	<link name="0">
		<visual>
			<geometry>
				<cylinder length="1.7939906307955067" radius="0.24029433729724395"/>
			</geometry>
		</visual>
		<collision>
			<geometry>
				<cylinder length="1.7939906307955067" radius="0.24029433729724395"/>
			</geometry>
		</collision>
		<inertial>
			<mass value="0.32542964784039335"/>
			<inertia ixx="0.03" iyy="0.03" izz="0.03" ixy="0" ixz="0" iyx="0"/>
		</inertial>
	</link>
	<link name="11">
		<visual>
			<geometry>
				<cylinder length="1.7402814386779732" radius="0.2514354642671235"/>
			</geometry>
		</visual>
		<collision>
			<geometry>
				<cylinder length="1.7402814386779732" radius="0.2514354642671235"/>
			</geometry>
		</collision>
		<inertial>
			<mass value="0.3456387518987746"/>
			<inertia ixx="0.03" iyy="0.03" izz="0.03" ixy="0" ixz="0" iyx="0"/>
		</inertial>
	</link>
	<link name="32">
		<visual>
			<geometry>
				<cylinder length="0.8006880350853647" radius="0.7018902028680317"/>
			</geometry>
		</visual>
		<collision>
			<geometry>
				<cylinder length="0.8006880350853647" radius="0.7018902028680317"/>
			</geometry>
		</collision>
		<inertial>
			<mass value="1.239229012397929"/>
			<inertia ixx="0.03" iyy="0.03" izz="0.03" ixy="0" ixz="0" iyx="0"/>
		</inertial>
	</link>
	<link name="33">
		<visual>
			<geometry>
				<cylinder length="0.8006880350853647" radius="0.7018902028680317"/>
			</geometry>
		</visual>
		<collision>
			<geometry>
				<cylinder length="0.8006880350853647" radius="0.7018902028680317"/>
			</geometry>
		</collision>
		<inertial>
			<mass value="1.239229012397929"/>
			<inertia ixx="0.03" iyy="0.03" izz="0.03" ixy="0" ixz="0" iyx="0"/>
		</inertial>
	</link>
	<link name="34">
		<visual>
			<geometry>
				<cylinder length="0.8006880350853647" radius="0.7018902028680317"/>
			</geometry>
		</visual>
		<collision>
			<geometry>
				<cylinder length="0.8006880350853647" radius="0.7018902028680317"/>
			</geometry>
		</collision>
		<inertial>
			<mass value="1.239229012397929"/>
			<inertia ixx="0.03" iyy="0.03" izz="0.03" ixy="0" ixz="0" iyx="0"/>
		</inertial>
	</link>
	<link name="15">
		<visual>
			<geometry>
				<cylinder length="1.7402814386779732" radius="0.2514354642671235"/>
			</geometry>
		</visual>
		<collision>
			<geometry>
				<cylinder length="1.7402814386779732" radius="0.2514354642671235"/>
			</geometry>
		</collision>
		<inertial>
			<mass value="0.3456387518987746"/>
			<inertia ixx="0.03" iyy="0.03" izz="0.03" ixy="0" ixz="0" iyx="0"/>
		</inertial>
	</link>
	<link name="36">
		<visual>
			<geometry>
				<cylinder length="0.8006880350853647" radius="0.7018902028680317"/>
			</geometry>
		</visual>
		<collision>
			<geometry>
				<cylinder length="0.8006880350853647" radius="0.7018902028680317"/>
			</geometry>
		</collision>
		<inertial>
			<mass value="1.239229012397929"/>
			<inertia ixx="0.03" iyy="0.03" izz="0.03" ixy="0" ixz="0" iyx="0"/>
		</inertial>
	</link>
	<link name="37">
		<visual>
			<geometry>
				<cylinder length="0.8006880350853647" radius="0.7018902028680317"/>
			</geometry>
		</visual>
		<collision>
			<geometry>
				<cylinder length="0.8006880350853647" radius="0.7018902028680317"/>
			</geometry>
		</collision>
		<inertial>
			<mass value="1.239229012397929"/>
			<inertia ixx="0.03" iyy="0.03" izz="0.03" ixy="0" ixz="0" iyx="0"/>
		</inertial>
	</link>
	<link name="38">
		<visual>
			<geometry>
				<cylinder length="0.8006880350853647" radius="0.7018902028680317"/>
			</geometry>
		</visual>
		<collision>
			<geometry>
				<cylinder length="0.8006880350853647" radius="0.7018902028680317"/>
			</geometry>
		</collision>
		<inertial>
			<mass value="1.239229012397929"/>
			<inertia ixx="0.03" iyy="0.03" izz="0.03" ixy="0" ixz="0" iyx="0"/>
		</inertial>
	</link>
	<link name="19">
		<visual>
			<geometry>
				<cylinder length="1.7402814386779732" radius="0.2514354642671235"/>
			</geometry>
		</visual>
		<collision>
			<geometry>
				<cylinder length="1.7402814386779732" radius="0.2514354642671235"/>
			</geometry>
		</collision>
		<inertial>
			<mass value="0.3456387518987746"/>
			<inertia ixx="0.03" iyy="0.03" izz="0.03" ixy="0" ixz="0" iyx="0"/>
		</inertial>
	</link>
	<link name="310">
		<visual>
			<geometry>
				<cylinder length="0.8006880350853647" radius="0.7018902028680317"/>
			</geometry>
		</visual>
		<collision>
			<geometry>
				<cylinder length="0.8006880350853647" radius="0.7018902028680317"/>
			</geometry>
		</collision>
		<inertial>
			<mass value="1.239229012397929"/>
			<inertia ixx="0.03" iyy="0.03" izz="0.03" ixy="0" ixz="0" iyx="0"/>
		</inertial>
	</link>
	<link name="311">
		<visual>
			<geometry>
				<cylinder length="0.8006880350853647" radius="0.7018902028680317"/>
			</geometry>
		</visual>
		<collision>
			<geometry>
				<cylinder length="0.8006880350853647" radius="0.7018902028680317"/>
			</geometry>
		</collision>
		<inertial>
			<mass value="1.239229012397929"/>
			<inertia ixx="0.03" iyy="0.03" izz="0.03" ixy="0" ixz="0" iyx="0"/>
		</inertial>
	</link>
	<link name="312">
		<visual>
			<geometry>
				<cylinder length="0.8006880350853647" radius="0.7018902028680317"/>
			</geometry>
		</visual>
		<collision>
			<geometry>
				<cylinder length="0.8006880350853647" radius="0.7018902028680317"/>
			</geometry>
		</collision>
		<inertial>
			<mass value="1.239229012397929"/>
			<inertia ixx="0.03" iyy="0.03" izz="0.03" ixy="0" ixz="0" iyx="0"/>
		</inertial>
	</link>
	<link name="213">
		<visual>
			<geometry>
				<cylinder length="1.337972422484723" radius="0.025258994624506426"/>
			</geometry>
		</visual>
		<collision>
			<geometry>
				<cylinder length="1.337972422484723" radius="0.025258994624506426"/>
			</geometry>
		</collision>
		<inertial>
			<mass value="0.0026818171007753355"/>
			<inertia ixx="0.03" iyy="0.03" izz="0.03" ixy="0" ixz="0" iyx="0"/>
		</inertial>
	</link>
	<link name="214">
		<visual>
			<geometry>
				<cylinder length="1.337972422484723" radius="0.025258994624506426"/>
			</geometry>
		</visual>
		<collision>
			<geometry>
				<cylinder length="1.337972422484723" radius="0.025258994624506426"/>
			</geometry>
		</collision>
		<inertial>
			<mass value="0.0026818171007753355"/>
			<inertia ixx="0.03" iyy="0.03" izz="0.03" ixy="0" ixz="0" iyx="0"/>
		</inertial>
	</link>
	<link name="215">
		<visual>
			<geometry>
				<cylinder length="1.337972422484723" radius="0.025258994624506426"/>
			</geometry>
		</visual>
		<collision>
			<geometry>
				<cylinder length="1.337972422484723" radius="0.025258994624506426"/>
			</geometry>
		</collision>
		<inertial>
			<mass value="0.0026818171007753355"/>
			<inertia ixx="0.03" iyy="0.03" izz="0.03" ixy="0" ixz="0" iyx="0"/>
		</inertial>
	</link>
	<joint name="11_to_0" type="revolute">
		<parent link="0"/>
		<child link="11"/>
		<axis xyz="1 0 0"/>
		<limit effort="1" upper="-3.1415" lower="3.1415" velocity="1"/>
		<origin rpy="3.5307818349792965 2.5065007603570355 4.342087598570308" xyz="0.7520576552854916 0.787909909003156 0.9999"/>
	</joint>
	<joint name="32_to_11" type="revolute">
		<parent link="11"/>
		<child link="32"/>
		<axis xyz="1 0 0"/>
		<limit effort="1" upper="-3.1415" lower="3.1415" velocity="1"/>
		<origin rpy="4.603555170688763 2.219797872154229 3.5593451118480086" xyz="0.2097322132230941 0.44888893503618466 0.10943685054020702"/>
	</joint>
	<joint name="33_to_11" type="revolute">
		<parent link="11"/>
		<child link="33"/>
		<axis xyz="1 0 0"/>
		<limit effort="1" upper="-3.1415" lower="3.1415" velocity="1"/>
		<origin rpy="6.905332756033144 2.219797872154229 3.5593451118480086" xyz="0.2097322132230941 0.44888893503618466 0.10943685054020702"/>
	</joint>
	<joint name="34_to_11" type="revolute">
		<parent link="11"/>
		<child link="34"/>
		<axis xyz="1 0 0"/>
		<limit effort="1" upper="-3.1415" lower="3.1415" velocity="1"/>
		<origin rpy="9.207110341377525 2.219797872154229 3.5593451118480086" xyz="0.2097322132230941 0.44888893503618466 0.10943685054020702"/>
	</joint>
	<joint name="15_to_0" type="revolute">
		<parent link="0"/>
		<child link="15"/>
		<axis xyz="1 0 0"/>
		<limit effort="1" upper="-3.1415" lower="3.1415" velocity="1"/>
		<origin rpy="5.296172752468944 2.5065007603570355 4.342087598570308" xyz="0.7520576552854916 0.787909909003156 0.9999"/>
	</joint>
	<joint name="36_to_15" type="revolute">
		<parent link="15"/>
		<child link="36"/>
		<axis xyz="1 0 0"/>
		<limit effort="1" upper="-3.1415" lower="3.1415" velocity="1"/>
		<origin rpy="4.603555170688763 2.219797872154229 3.5593451118480086" xyz="0.2097322132230941 0.44888893503618466 0.10943685054020702"/>
	</joint>
	<joint name="37_to_15" type="revolute">
		<parent link="15"/>
		<child link="37"/>
		<axis xyz="1 0 0"/>
		<limit effort="1" upper="-3.1415" lower="3.1415" velocity="1"/>
		<origin rpy="6.905332756033144 2.219797872154229 3.5593451118480086" xyz="0.2097322132230941 0.44888893503618466 0.10943685054020702"/>
	</joint>
	<joint name="38_to_15" type="revolute">
		<parent link="15"/>
		<child link="38"/>
		<axis xyz="1 0 0"/>
		<limit effort="1" upper="-3.1415" lower="3.1415" velocity="1"/>
		<origin rpy="9.207110341377525 2.219797872154229 3.5593451118480086" xyz="0.2097322132230941 0.44888893503618466 0.10943685054020702"/>
	</joint>
	<joint name="19_to_0" type="revolute">
		<parent link="0"/>
		<child link="19"/>
		<axis xyz="1 0 0"/>
		<limit effort="1" upper="-3.1415" lower="3.1415" velocity="1"/>
		<origin rpy="7.061563669958593 2.5065007603570355 4.342087598570308" xyz="0.7520576552854916 0.787909909003156 0.9999"/>
	</joint>
	<joint name="310_to_19" type="revolute">
		<parent link="19"/>
		<child link="310"/>
		<axis xyz="1 0 0"/>
		<limit effort="1" upper="-3.1415" lower="3.1415" velocity="1"/>
		<origin rpy="4.603555170688763 2.219797872154229 3.5593451118480086" xyz="0.2097322132230941 0.44888893503618466 0.10943685054020702"/>
	</joint>
	<joint name="311_to_19" type="revolute">
		<parent link="19"/>
		<child link="311"/>
		<axis xyz="1 0 0"/>
		<limit effort="1" upper="-3.1415" lower="3.1415" velocity="1"/>
		<origin rpy="6.905332756033144 2.219797872154229 3.5593451118480086" xyz="0.2097322132230941 0.44888893503618466 0.10943685054020702"/>
	</joint>
	<joint name="312_to_19" type="revolute">
		<parent link="19"/>
		<child link="312"/>
		<axis xyz="1 0 0"/>
		<limit effort="1" upper="-3.1415" lower="3.1415" velocity="1"/>
		<origin rpy="9.207110341377525 2.219797872154229 3.5593451118480086" xyz="0.2097322132230941 0.44888893503618466 0.10943685054020702"/>
	</joint>
	<joint name="213_to_0" type="revolute">
		<parent link="0"/>
		<child link="213"/>
		<axis xyz="0 1 0"/>
		<limit effort="1" upper="-3.1415" lower="3.1415" velocity="1"/>
		<origin rpy="12.91937015870154 1.7977758134575648 5.593589069951501" xyz="0.6345604679540542 0.1174361008392818 0.7225051083317479"/>
	</joint>
	<joint name="214_to_0" type="revolute">
		<parent link="0"/>
		<child link="214"/>
		<axis xyz="0 1 0"/>
		<limit effort="1" upper="-3.1415" lower="3.1415" velocity="1"/>
		<origin rpy="15.503244190441848 1.7977758134575648 5.593589069951501" xyz="0.6345604679540542 0.1174361008392818 0.7225051083317479"/>
	</joint>
	<joint name="215_to_0" type="revolute">
		<parent link="0"/>
		<child link="215"/>
		<axis xyz="0 1 0"/>
		<limit effort="1" upper="-3.1415" lower="3.1415" velocity="1"/>
		<origin rpy="18.087118222182156 1.7977758134575648 5.593589069951501" xyz="0.6345604679540542 0.1174361008392818 0.7225051083317479"/>
	</joint>
</robot>
