<?xml version="1.0"?><robot name="pepe">
	<link name="0">
		<visual>
			<geometry>
				<cylinder length="1.9998" radius="0.6921462447369557"/>
			</geometry>
		</visual>
		<collision>
			<geometry>
				<cylinder length="1.9998" radius="0.6921462447369557"/>
			</geometry>
		</collision>
		<inertial>
			<mass value="3.009762110778277"/>
			<inertia ixx="0.03" iyy="0.03" izz="0.03" ixy="0" ixz="0" iyx="0"/>
		</inertial>
	</link>
	<link name="11">
		<visual>
			<geometry>
				<cylinder length="1.9998" radius="0.9999"/>
			</geometry>
		</visual>
		<collision>
			<geometry>
				<cylinder length="1.9998" radius="0.9999"/>
			</geometry>
		</collision>
		<inertial>
			<mass value="6.281300540076709"/>
			<inertia ixx="0.03" iyy="0.03" izz="0.03" ixy="0" ixz="0" iyx="0"/>
		</inertial>
	</link>
	<link name="22">
		<visual>
			<geometry>
				<cylinder length="1.0088065689502967" radius="0.7707189348450902"/>
			</geometry>
		</visual>
		<collision>
			<geometry>
				<cylinder length="1.0088065689502967" radius="0.7707189348450902"/>
			</geometry>
		</collision>
		<inertial>
			<mass value="1.8825643566191614"/>
			<inertia ixx="0.03" iyy="0.03" izz="0.03" ixy="0" ixz="0" iyx="0"/>
		</inertial>
	</link>
	<link name="23">
		<visual>
			<geometry>
				<cylinder length="1.0088065689502967" radius="0.7707189348450902"/>
			</geometry>
		</visual>
		<collision>
			<geometry>
				<cylinder length="1.0088065689502967" radius="0.7707189348450902"/>
			</geometry>
		</collision>
		<inertial>
			<mass value="1.8825643566191614"/>
			<inertia ixx="0.03" iyy="0.03" izz="0.03" ixy="0" ixz="0" iyx="0"/>
		</inertial>
	</link>
	<link name="14">
		<visual>
			<geometry>
				<cylinder length="1.9998" radius="0.9999"/>
			</geometry>
		</visual>
		<collision>
			<geometry>
				<cylinder length="1.9998" radius="0.9999"/>
			</geometry>
		</collision>
		<inertial>
			<mass value="6.281300540076709"/>
			<inertia ixx="0.03" iyy="0.03" izz="0.03" ixy="0" ixz="0" iyx="0"/>
		</inertial>
	</link>
	<link name="25">
		<visual>
			<geometry>
				<cylinder length="1.0088065689502967" radius="0.7707189348450902"/>
			</geometry>
		</visual>
		<collision>
			<geometry>
				<cylinder length="1.0088065689502967" radius="0.7707189348450902"/>
			</geometry>
		</collision>
		<inertial>
			<mass value="1.8825643566191614"/>
			<inertia ixx="0.03" iyy="0.03" izz="0.03" ixy="0" ixz="0" iyx="0"/>
		</inertial>
	</link>
	<link name="26">
		<visual>
			<geometry>
				<cylinder length="1.0088065689502967" radius="0.7707189348450902"/>
			</geometry>
		</visual>
		<collision>
			<geometry>
				<cylinder length="1.0088065689502967" radius="0.7707189348450902"/>
			</geometry>
		</collision>
		<inertial>
			<mass value="1.8825643566191614"/>
			<inertia ixx="0.03" iyy="0.03" izz="0.03" ixy="0" ixz="0" iyx="0"/>
		</inertial>
	</link>
	<joint name="11_to_0" type="revolute">
		<parent link="0"/>
		<child link="11"/>
		<axis xyz="1 0 0"/>
		<limit effort="1" upper="-3.1415" lower="3.1415" velocity="1"/>
		<origin rpy="3.011078914222512 6.282556988648868 0.23221567026121676" xyz="0.38510891560579563 0.34321537469017627 0.08051966649087028"/>
	</joint>
	<joint name="22_to_11" type="revolute">
		<parent link="11"/>
		<child link="22"/>
		<axis xyz="0 1 0"/>
		<limit effort="1" upper="-3.1415" lower="3.1415" velocity="1"/>
		<origin rpy="12.565113977297736 4.130193121910501 4.541234158045601" xyz="0.6465744440019845 0.3185629063362395 0.9856707806421344"/>
	</joint>
	<joint name="23_to_11" type="revolute">
		<parent link="11"/>
		<child link="23"/>
		<axis xyz="0 1 0"/>
		<limit effort="1" upper="-3.1415" lower="3.1415" velocity="1"/>
		<origin rpy="18.847670965946605 4.130193121910501 4.541234158045601" xyz="0.6465744440019845 0.3185629063362395 0.9856707806421344"/>
	</joint>
	<joint name="14_to_0" type="revolute">
		<parent link="0"/>
		<child link="14"/>
		<axis xyz="1 0 0"/>
		<limit effort="1" upper="-3.1415" lower="3.1415" velocity="1"/>
		<origin rpy="4.5166183713337675 6.282556988648868 0.23221567026121676" xyz="0.38510891560579563 0.34321537469017627 0.08051966649087028"/>
	</joint>
	<joint name="25_to_14" type="revolute">
		<parent link="14"/>
		<child link="25"/>
		<axis xyz="0 1 0"/>
		<limit effort="1" upper="-3.1415" lower="3.1415" velocity="1"/>
		<origin rpy="12.565113977297736 4.130193121910501 4.541234158045601" xyz="0.6465744440019845 0.3185629063362395 0.9856707806421344"/>
	</joint>
	<joint name="26_to_14" type="revolute">
		<parent link="14"/>
		<child link="26"/>
		<axis xyz="0 1 0"/>
		<limit effort="1" upper="-3.1415" lower="3.1415" velocity="1"/>
		<origin rpy="18.847670965946605 4.130193121910501 4.541234158045601" xyz="0.6465744440019845 0.3185629063362395 0.9856707806421344"/>
	</joint>
</robot>
