<?xml version="1.0"?><robot name="pepe">
	<link name="0">
		<visual>
			<geometry>
				<cylinder length="1.9998" radius="0.920679236108968"/>
			</geometry>
		</visual>
		<collision>
			<geometry>
				<cylinder length="1.9998" radius="0.920679236108968"/>
			</geometry>
		</collision>
		<inertial>
			<mass value="5.325411038520067"/>
			<inertia ixx="0.03" iyy="0.03" izz="0.03" ixy="0" ixz="0" iyx="0"/>
		</inertial>
	</link>
	<link name="11">
		<visual>
			<geometry>
				<cylinder length="1.3897543118212539" radius="0.8377216470649189"/>
			</geometry>
		</visual>
		<collision>
			<geometry>
				<cylinder length="1.3897543118212539" radius="0.8377216470649189"/>
			</geometry>
		</collision>
		<inertial>
			<mass value="3.063990248021326"/>
			<inertia ixx="0.03" iyy="0.03" izz="0.03" ixy="0" ixz="0" iyx="0"/>
		</inertial>
	</link>
	<joint name="11_to_0" type="revolute">
		<parent link="0"/>
		<child link="11"/>
		<axis xyz="0 1 0"/>
		<limit effort="1" upper="-3.1415" lower="3.1415" velocity="1"/>
		<origin rpy="8.963030129196884 4.258849670329692 0.6333811768262183" xyz="0.9802248488304317 0.576453298275668 0.714552166094369"/>
	</joint>
</robot>
