<?xml version="1.0"?><robot name="pepe">
	<link name="0">
		<visual>
			<geometry>
				<cylinder length="0.35070417612288685" radius="0.6852106303938267"/>
			</geometry>
		</visual>
		<collision>
			<geometry>
				<cylinder length="0.35070417612288685" radius="0.6852106303938267"/>
			</geometry>
		</collision>
		<inertial>
			<mass value="0.5172958498018503"/>
			<inertia ixx="0.03" iyy="0.03" izz="0.03" ixy="0" ixz="0" iyx="0"/>
		</inertial>
	</link>
	<link name="11">
		<visual>
			<geometry>
				<cylinder length="1.0075182646623542" radius="0.5664443832053537"/>
			</geometry>
		</visual>
		<collision>
			<geometry>
				<cylinder length="1.0075182646623542" radius="0.5664443832053537"/>
			</geometry>
		</collision>
		<inertial>
			<mass value="1.015587507572395"/>
			<inertia ixx="0.03" iyy="0.03" izz="0.03" ixy="0" ixz="0" iyx="0"/>
		</inertial>
	</link>
	<link name="22">
		<visual>
			<geometry>
				<cylinder length="1.2610415938423205" radius="0.04911858883839093"/>
			</geometry>
		</visual>
		<collision>
			<geometry>
				<cylinder length="1.2610415938423205" radius="0.04911858883839093"/>
			</geometry>
		</collision>
		<inertial>
			<mass value="0.009558088479673975"/>
			<inertia ixx="0.03" iyy="0.03" izz="0.03" ixy="0" ixz="0" iyx="0"/>
		</inertial>
	</link>
	<link name="23">
		<visual>
			<geometry>
				<cylinder length="1.2610415938423205" radius="0.04911858883839093"/>
			</geometry>
		</visual>
		<collision>
			<geometry>
				<cylinder length="1.2610415938423205" radius="0.04911858883839093"/>
			</geometry>
		</collision>
		<inertial>
			<mass value="0.009558088479673975"/>
			<inertia ixx="0.03" iyy="0.03" izz="0.03" ixy="0" ixz="0" iyx="0"/>
		</inertial>
	</link>
	<link name="24">
		<visual>
			<geometry>
				<cylinder length="1.2610415938423205" radius="0.04911858883839093"/>
			</geometry>
		</visual>
		<collision>
			<geometry>
				<cylinder length="1.2610415938423205" radius="0.04911858883839093"/>
			</geometry>
		</collision>
		<inertial>
			<mass value="0.009558088479673975"/>
			<inertia ixx="0.03" iyy="0.03" izz="0.03" ixy="0" ixz="0" iyx="0"/>
		</inertial>
	</link>
	<link name="35">
		<visual>
			<geometry>
				<cylinder length="0.23527883295165508" radius="0.953792481301108"/>
			</geometry>
		</visual>
		<collision>
			<geometry>
				<cylinder length="0.23527883295165508" radius="0.953792481301108"/>
			</geometry>
		</collision>
		<inertial>
			<mass value="0.6724198402753442"/>
			<inertia ixx="0.03" iyy="0.03" izz="0.03" ixy="0" ixz="0" iyx="0"/>
		</inertial>
	</link>
	<link name="36">
		<visual>
			<geometry>
				<cylinder length="0.23527883295165508" radius="0.953792481301108"/>
			</geometry>
		</visual>
		<collision>
			<geometry>
				<cylinder length="0.23527883295165508" radius="0.953792481301108"/>
			</geometry>
		</collision>
		<inertial>
			<mass value="0.6724198402753442"/>
			<inertia ixx="0.03" iyy="0.03" izz="0.03" ixy="0" ixz="0" iyx="0"/>
		</inertial>
	</link>
	<joint name="11_to_0" type="revolute">
		<parent link="0"/>
		<child link="11"/>
		<axis xyz="0 0 1"/>
		<limit effort="1" upper="-3.1415" lower="3.1415" velocity="1"/>
		<origin rpy="7.517099752517243 1.9967120255464816 5.1403467964114" xyz="0.36813298449497434 0.8011075333734261 0.1889147050062893"/>
	</joint>
	<joint name="22_to_11" type="revolute">
		<parent link="11"/>
		<child link="22"/>
		<axis xyz="0 0 1"/>
		<limit effort="1" upper="-3.1415" lower="3.1415" velocity="1"/>
		<origin rpy="3.9995369568553443 1.743286167099876 1.4519012211936142" xyz="0.6347812771404477 0.6119682614187647 0.3344417075701225"/>
	</joint>
	<joint name="23_to_11" type="revolute">
		<parent link="11"/>
		<child link="23"/>
		<axis xyz="0 0 1"/>
		<limit effort="1" upper="-3.1415" lower="3.1415" velocity="1"/>
		<origin rpy="5.999305435283016 1.743286167099876 1.4519012211936142" xyz="0.6347812771404477 0.6119682614187647 0.3344417075701225"/>
	</joint>
	<joint name="24_to_11" type="revolute">
		<parent link="11"/>
		<child link="24"/>
		<axis xyz="0 0 1"/>
		<limit effort="1" upper="-3.1415" lower="3.1415" velocity="1"/>
		<origin rpy="7.9990739137106885 1.743286167099876 1.4519012211936142" xyz="0.6347812771404477 0.6119682614187647 0.3344417075701225"/>
	</joint>
	<joint name="35_to_0" type="revolute">
		<parent link="0"/>
		<child link="35"/>
		<axis xyz="0 0 1"/>
		<limit effort="1" upper="-3.1415" lower="3.1415" velocity="1"/>
		<origin rpy="9.5085681265624 6.23516656721417 4.324522601096396" xyz="0.11890645986740592 0.4579153726494829 0.42703088069694617"/>
	</joint>
	<joint name="36_to_0" type="revolute">
		<parent link="0"/>
		<child link="36"/>
		<axis xyz="0 0 1"/>
		<limit effort="1" upper="-3.1415" lower="3.1415" velocity="1"/>
		<origin rpy="12.678090835416533 6.23516656721417 4.324522601096396" xyz="0.11890645986740592 0.4579153726494829 0.42703088069694617"/>
	</joint>
</robot>
