<?xml version="1.0"?><robot name="pepe">
	<link name="0">
		<visual>
			<geometry>
				<cylinder length="1.7402814386779732" radius="0.2514354642671235"/>
			</geometry>
		</visual>
		<collision>
			<geometry>
				<cylinder length="1.7402814386779732" radius="0.2514354642671235"/>
			</geometry>
		</collision>
		<inertial>
			<mass value="0.3456387518987746"/>
			<inertia ixx="0.03" iyy="0.03" izz="0.03" ixy="0" ixz="0" iyx="0"/>
		</inertial>
	</link>
	<link name="11">
		<visual>
			<geometry>
				<cylinder length="1.483124314361728" radius="0.6358135889807587"/>
			</geometry>
		</visual>
		<collision>
			<geometry>
				<cylinder length="1.483124314361728" radius="0.6358135889807587"/>
			</geometry>
		</collision>
		<inertial>
			<mass value="1.8835928743458918"/>
			<inertia ixx="0.03" iyy="0.03" izz="0.03" ixy="0" ixz="0" iyx="0"/>
		</inertial>
	</link>
	<link name="22">
		<visual>
			<geometry>
				<cylinder length="0.6006880350853647" radius="0.7018902028680317"/>
			</geometry>
		</visual>
		<collision>
			<geometry>
				<cylinder length="0.6006880350853647" radius="0.7018902028680317"/>
			</geometry>
		</collision>
		<inertial>
			<mass value="0.9296879781633387"/>
			<inertia ixx="0.03" iyy="0.03" izz="0.03" ixy="0" ixz="0" iyx="0"/>
		</inertial>
	</link>
	<link name="23">
		<visual>
			<geometry>
				<cylinder length="0.6006880350853647" radius="0.7018902028680317"/>
			</geometry>
		</visual>
		<collision>
			<geometry>
				<cylinder length="0.6006880350853647" radius="0.7018902028680317"/>
			</geometry>
		</collision>
		<inertial>
			<mass value="0.9296879781633387"/>
			<inertia ixx="0.03" iyy="0.03" izz="0.03" ixy="0" ixz="0" iyx="0"/>
		</inertial>
	</link>
	<link name="24">
		<visual>
			<geometry>
				<cylinder length="0.6006880350853647" radius="0.7018902028680317"/>
			</geometry>
		</visual>
		<collision>
			<geometry>
				<cylinder length="0.6006880350853647" radius="0.7018902028680317"/>
			</geometry>
		</collision>
		<inertial>
			<mass value="0.9296879781633387"/>
			<inertia ixx="0.03" iyy="0.03" izz="0.03" ixy="0" ixz="0" iyx="0"/>
		</inertial>
	</link>
	<joint name="11_to_0" type="revolute">
		<parent link="0"/>
		<child link="11"/>
		<axis xyz="0 0 1"/>
		<limit effort="1" upper="-3.1415" lower="3.1415" velocity="1"/>
		<origin rpy="7.990417573566668 3.383946299899582 1.553446088233857" xyz="0.875913495298717 0.9648455558761536 0.3898030649287467"/>
	</joint>
	<joint name="22_to_0" type="revolute">
		<parent link="0"/>
		<child link="22"/>
		<axis xyz="0 1 0"/>
		<limit effort="1" upper="-3.1415" lower="3.1415" velocity="1"/>
		<origin rpy="10.675243940340895 2.8481164028721877 3.5593451118480086" xyz="0.2097322132230941 0.3488889350361847 0.10943685054020702"/>
	</joint>
	<joint name="23_to_0" type="revolute">
		<parent link="0"/>
		<child link="23"/>
		<axis xyz="0 1 0"/>
		<limit effort="1" upper="-3.1415" lower="3.1415" velocity="1"/>
		<origin rpy="14.233658587121194 2.8481164028721877 3.5593451118480086" xyz="0.2097322132230941 0.3488889350361847 0.10943685054020702"/>
	</joint>
	<joint name="24_to_0" type="revolute">
		<parent link="0"/>
		<child link="24"/>
		<axis xyz="0 1 0"/>
		<limit effort="1" upper="-3.1415" lower="3.1415" velocity="1"/>
		<origin rpy="17.792073233901494 2.8481164028721877 3.5593451118480086" xyz="0.2097322132230941 0.3488889350361847 0.10943685054020702"/>
	</joint>
</robot>
