<?xml version="1.0"?><robot name="pepe">
	<link name="0">
		<visual>
			<geometry>
				<cylinder length="0.41703708533247724" radius="0.24510129433127736"/>
			</geometry>
		</visual>
		<collision>
			<geometry>
				<cylinder length="0.41703708533247724" radius="0.24510129433127736"/>
			</geometry>
		</collision>
		<inertial>
			<mass value="0.07870743487701207"/>
			<inertia ixx="0.03" iyy="0.03" izz="0.03" ixy="0" ixz="0" iyx="0"/>
		</inertial>
	</link>
	<link name="11">
		<visual>
			<geometry>
				<cylinder length="1.7939906307955067" radius="0.24029433729724395"/>
			</geometry>
		</visual>
		<collision>
			<geometry>
				<cylinder length="1.7939906307955067" radius="0.24029433729724395"/>
			</geometry>
		</collision>
		<inertial>
			<mass value="0.32542964784039335"/>
			<inertia ixx="0.03" iyy="0.03" izz="0.03" ixy="0" ixz="0" iyx="0"/>
		</inertial>
	</link>
	<link name="22">
		<visual>
			<geometry>
				<cylinder length="1.7402814386779732" radius="0.2514354642671235"/>
			</geometry>
		</visual>
		<collision>
			<geometry>
				<cylinder length="1.7402814386779732" radius="0.2514354642671235"/>
			</geometry>
		</collision>
		<inertial>
			<mass value="0.3456387518987746"/>
			<inertia ixx="0.03" iyy="0.03" izz="0.03" ixy="0" ixz="0" iyx="0"/>
		</inertial>
	</link>
	<link name="23">
		<visual>
			<geometry>
				<cylinder length="1.7402814386779732" radius="0.2514354642671235"/>
			</geometry>
		</visual>
		<collision>
			<geometry>
				<cylinder length="1.7402814386779732" radius="0.2514354642671235"/>
			</geometry>
		</collision>
		<inertial>
			<mass value="0.3456387518987746"/>
			<inertia ixx="0.03" iyy="0.03" izz="0.03" ixy="0" ixz="0" iyx="0"/>
		</inertial>
	</link>
	<link name="24">
		<visual>
			<geometry>
				<cylinder length="1.7402814386779732" radius="0.2514354642671235"/>
			</geometry>
		</visual>
		<collision>
			<geometry>
				<cylinder length="1.7402814386779732" radius="0.2514354642671235"/>
			</geometry>
		</collision>
		<inertial>
			<mass value="0.3456387518987746"/>
			<inertia ixx="0.03" iyy="0.03" izz="0.03" ixy="0" ixz="0" iyx="0"/>
		</inertial>
	</link>
	<link name="35">
		<visual>
			<geometry>
				<cylinder length="1.337972422484723" radius="0.025258994624506426"/>
			</geometry>
		</visual>
		<collision>
			<geometry>
				<cylinder length="1.337972422484723" radius="0.025258994624506426"/>
			</geometry>
		</collision>
		<inertial>
			<mass value="0.0026818171007753355"/>
			<inertia ixx="0.03" iyy="0.03" izz="0.03" ixy="0" ixz="0" iyx="0"/>
		</inertial>
	</link>
	<link name="36">
		<visual>
			<geometry>
				<cylinder length="1.337972422484723" radius="0.025258994624506426"/>
			</geometry>
		</visual>
		<collision>
			<geometry>
				<cylinder length="1.337972422484723" radius="0.025258994624506426"/>
			</geometry>
		</collision>
		<inertial>
			<mass value="0.0026818171007753355"/>
			<inertia ixx="0.03" iyy="0.03" izz="0.03" ixy="0" ixz="0" iyx="0"/>
		</inertial>
	</link>
	<link name="37">
		<visual>
			<geometry>
				<cylinder length="1.337972422484723" radius="0.025258994624506426"/>
			</geometry>
		</visual>
		<collision>
			<geometry>
				<cylinder length="1.337972422484723" radius="0.025258994624506426"/>
			</geometry>
		</collision>
		<inertial>
			<mass value="0.0026818171007753355"/>
			<inertia ixx="0.03" iyy="0.03" izz="0.03" ixy="0" ixz="0" iyx="0"/>
		</inertial>
	</link>
	<joint name="11_to_0" type="revolute">
		<parent link="0"/>
		<child link="11"/>
		<axis xyz="0 1 0"/>
		<limit effort="1" upper="-3.1415" lower="3.1415" velocity="1"/>
		<origin rpy="6.897320077721064 2.2458082970001523 3.4178430874805397" xyz="0.3684942285678249 0.47884957059801336 0.8017108469487813"/>
	</joint>
	<joint name="22_to_11" type="revolute">
		<parent link="11"/>
		<child link="22"/>
		<axis xyz="1 0 0"/>
		<limit effort="1" upper="-3.1415" lower="3.1415" velocity="1"/>
		<origin rpy="3.5307818349792965 2.5065007603570355 4.342087598570308" xyz="0.7520576552854916 0.787909909003156 0.9858630834839593"/>
	</joint>
	<joint name="23_to_11" type="revolute">
		<parent link="11"/>
		<child link="23"/>
		<axis xyz="1 0 0"/>
		<limit effort="1" upper="-3.1415" lower="3.1415" velocity="1"/>
		<origin rpy="5.296172752468944 2.5065007603570355 4.342087598570308" xyz="0.7520576552854916 0.787909909003156 0.9858630834839593"/>
	</joint>
	<joint name="24_to_11" type="revolute">
		<parent link="11"/>
		<child link="24"/>
		<axis xyz="1 0 0"/>
		<limit effort="1" upper="-3.1415" lower="3.1415" velocity="1"/>
		<origin rpy="7.061563669958593 2.5065007603570355 4.342087598570308" xyz="0.7520576552854916 0.787909909003156 0.9858630834839593"/>
	</joint>
	<joint name="35_to_0" type="revolute">
		<parent link="0"/>
		<child link="35"/>
		<axis xyz="0 0 1"/>
		<limit effort="1" upper="-3.1415" lower="3.1415" velocity="1"/>
		<origin rpy="5.866666503067048 1.7977758134575648 5.593589069951501" xyz="0.6345604679540542 0.1174361008392818 0.7225051083317479"/>
	</joint>
	<joint name="36_to_0" type="revolute">
		<parent link="0"/>
		<child link="36"/>
		<axis xyz="0 0 1"/>
		<limit effort="1" upper="-3.1415" lower="3.1415" velocity="1"/>
		<origin rpy="7.822222004089397 1.7977758134575648 5.593589069951501" xyz="0.6345604679540542 0.1174361008392818 0.7225051083317479"/>
	</joint>
	<joint name="37_to_0" type="revolute">
		<parent link="0"/>
		<child link="37"/>
		<axis xyz="0 0 1"/>
		<limit effort="1" upper="-3.1415" lower="3.1415" velocity="1"/>
		<origin rpy="9.777777505111747 1.7977758134575648 5.593589069951501" xyz="0.6345604679540542 0.1174361008392818 0.7225051083317479"/>
	</joint>
</robot>
